Workbook

Sheet sheet1
A1: Sr. No. | B1: Catogery | C1: Key Responsibility (KR) | D1: KR Discriptions | E1: Frequency | F1: Weightage | G1: Metrics
A2: 1 | B2: Sort Center | C2: SC Vol. & Manpower | D2: 1. Flaging up if any manpower deep or over/lower attainment of vol. 2. Sharing fortnighlty Vol. projection with partner and alignement. | E2: Daily | F2: 0.05 | G2: No Esclation
A3: 2 | C3: SC Inbound and landing | D3: 2. NLH TAT validation and landing profile. | E3: As on when some changes happeing. | F3: 0.05 | G3: No Esclation
A4: 3 | C4: SC DoD Operation and Losses reduction | D4: 1. Working with SC partner for efficient Operation. 2. Ageing control and IRT, label and other exception handling. 3. At facility hardstop losses reduction. 4. COD timely RTO marking and clerance. 5. Daily internal review call participation. 6. Tracker validation and timely update. Internal review, Daily node comliance RCA, Attempt Compliance NLH & At facility breach RCA . | E4: Daily | F4: 0.4 | G4: 1. Node Complaince - > 95%. 2. Bagging Compliance - > 98% 3. At facility losses - < 100 PPM 4. COD > 4 days - ZERO 5. SC Attempt Compliance : >1%
A5: 4 | C5: IB Pendency & Clerance | D5: 1. End to end RCA and control on "at facility" , "Shortage marked" and IB Intransit IB pendency. 2. Recon and pendency closure with upstream nodes on shortage and Intransit pendency. 3. IB Losses reduction and visibility. | E5: Daily | F5: 0.2 | G5: 1. Shortage marked Unresolved : 0.001%. 2. IB Intransit losses : 100 PPM 3. NLH landing performance : > 80% 4. At facility losses : < 100 PPM
A6: 5 | B6: Transportation | C6: OB Pendency & Clerance | D6: 1. End to end control and updates on "OB Intransit" and "Shortage assigned" pendency. 2. Recon and pendecy closure with down stream nodes. 3. Shortage assigned and OB Intransit losses reduction and visibility. | E6: Daily | F6: 0.2 | G6: 1. Shortage assigned Unresolved : 0.001%. 2. OB Intransit losses : 100 PPM
A7: 6 | C7: RLH Design and Utilisation | D7: 1. Maintain the Optimal design coverage of the facility 2. Identify and control RLH design deviation, lower/higher utilisation routes fix it. | E7: When design falls below 95% | F7: 0.05 | G7: 1. Design Coverage : > 95% 2. No escaltion.
A8: 7 | C8: RLH Operation and vendors management | D8: 1. E2E vendor performance management. 2. Route allocation and reduction as per the busssiness requirements. 2. Fixing the Open issues like on-time trip rceipt, POD receipt etc 3. Daily, weekly and Monthly performance visibility. 4. Updating Finance/RLH tracker on D+1. 5. Daily internal review call participation. 6. Validation and timely update of all the trackers like Internal review tracker,vendors input trackers and attempt compliance RLH breaches RCA. | E8: Daily | F8: 0.4 | G8: 1. RLH Attempt Complaince : < 5% 2. Vendor placement and delivery performance : > 95% 3. Finance tracker update : D+1 4. Tracker update completion : D+1
A9: 8 | C9: RLH Cost Control, vendor staboility and Competition | D9: 1. Keeping a track on vehciles utilisation and initiating actions to ensure the maximum utilisation. 2. Vendor wise monthly CPS visibility and Cost reduction initiatives, Starting floating route's. | E9: Daily & Monthly | F9: 0.05 | G9: 1. No over/lower utilisation callout. 2. CPS target : < 4 INR
A10: 9 | B10: Sort Codes Management & Facility layout | C10: Sort Code creation and load balancing. | D10: 1. Cut off/route wise sort code creation needs to be shared within 24 hrs of tagging, if complete information available in the tracker. 2. Stationwise vol balancing and route mapping. 3. Zone to Grid mapping. 4. Maintain the stardard facility laypout and control. | E10: Within 24hrs of request. | F10: 0.15 | G10: 1. Sort code pending should be Zero on > 2 days. 2. Uniform load distribution across all the sorting zones. 3. Zone to Grid mapping accuracy should be > 100% 4. No deviation on standard faciltiy layout and design.
A11: 10 | B11: Consumables | C11: Consumables availability and replenishment and distribution | D11: 1. Track the consumables Inventrory and fullfillment. 2. Ensuring no inventory shortfall. | E11: Daily | F11: 0.05 | G11: 1. Zero shortfall of the consumables Inventory. 2. Consumables daily tracker update.
A12: 11 | B12: Scrap Management | C12: End to End Scrap Management | D12: 1. Regular check of sracp generation (Damage bags, used tags, used bolt seal, corrigated boxes and Lost/damaged, Delivered/duplicate) and plan liqudation. 2. Vendor billing and payment tracking. | E12: Weekly | F12: 0.05 | G12: 1. No accumlation of scraps at the facility. 2. Scrap disposal timely tracker update, Invoice creation and payment closure. 3. In case of Damaged/Duplicate shipment dispoal advanced Delivery Challan creation.
A13: 12 | B13: Excellence Drive | C13: Process Improvements | D13: 1. Improvement initiatives, Kaizens Submission and new new idea for the system excellence. | E13: In general | F13: 0.1 | G13: Montly kaizen/Improvement idea submisson : 1
E16: Sort Center & Other | F16: 1
E17: Transport & Other | F17: 1

Sheet sheet2
A1: Facility Code | B1: Zone | C1: Active Status | D1: Regional Head | E1: Regional Head Mail id | F1: Regional Head Mobile Number | G1: Cluster Head | H1: Cluster Head Mail id | I1: Cluster Head Mobile Number | J1: Area Manager 1 | K1: AM1 Mail id | L1: AM1 Mobile Number | M1: Area Manager 2 | N1: AM2 Mail id | O1: AM2 Mobile Number | P1: Area Manager 3 | Q1: AM3 Mail id | R1: AM3 Mobile Number
A2: AHS | B2: West | C2: Active | D2: Tushar Dongare | E2: tushar.dongare@meesho.com | F2: 8007696417 | G2: Siddharth Chhibber | H2: siddharth.chhibber@meesho.com | I2: 8160593572 | J2: Prakash Lokhande | K2: lokhnade.prakash@meesho.com | L2: 9173700204 | M2: Vishal Mistri | N2: vishal.mistri@meesho.com | O2: 8160776092
A3: BLS | B3: South | C3: Active | D3: Vikrant Pandey | E3: vikrant.pandey@meesho.com | F3: 98030 91594 | G3: Sujesh S | H3: Sujesh.s@meesho.com | I3: 9497320464 | J3: Shivaraj | K3: shivraj.a@meesho.com | L3: 90366 61602 | M3: Gowtham | N3: gowtham.bs@meesho.com | O3: 9663575036
A4: HBS | B4: South | C4: Active | D4: Vikrant Pandey | E4: vikrant.pandey@meesho.com | F4: 98030 91594 | G4: Chamar | H4: chamar.munda1@meesho.com | I4: 6363387963 | J4: Kishore K L | K4: kishor.kl@meesho.com | L4: 7090078440 | M4: Kalyan Reddy | N4: kalyan.reddy@meesho.com | O4: 9164532362
A5: BWS | B5: West | C5: Active | D5: Ajit Gajana Vedak | E5: ajit.vedak@meesho.com | F5: 9004551388 | G5: Suresh Behera | H5: Suresh.behera@meesho.com | I5: 8355872770 | J5: Awwab Kirme | K5: awwab.kirme@meesho.com | L5: 8888726472 | M5: Sagar Rajkumar Khaple | N5: sagar.khaple@meesho.com | O5: 7738879336 | Q5: deepraj.deshmukh@meesho.com | R5: 9226395808
A6: MIS | B6: West | C6: Active | D6: Ajit Gajana Vedak | E6: ajit.vedak@meesho.com | F6: 9004551388 | G6: Abhishek Mhamunkar | H6: abhishek.mhamunkar@meesho.com/manohar.singh@meesho.com | I6: 9969276834/9992913292 | J6: Amar Pansare | K6: amar.pansare@meesho.com | L6: 7767908097 | M6: Rahul Thakare | N6: rahul.thakare@meesho.com | O6: 9922621942
A7: BHS | B7: West | C7: Inactive | D7: Ajit Gajana Vedak | E7: ajit.vedak@meesho.com | F7: 9004551388 | G7: Axendra Singh Chouhan | H7: axendra.chouhan@meesho.com | I7: 7024477807 | J7: Deepak Sharma | K7: deepak.sharma3@meesho.com | L7: 8591085838 | M7: Diwakar saurabh kumar chandrika prasad | N7: saurabhkumar.prashad@meesho.com | O7: 8483900198 | P7: Rajneesh Singh | Q7: rajneesh.singh@meesho.com | R7: 8109234404
A8: BUS | B8: East | C8: Active | D8: Banit Roy | E8: banit.roy@meesho.com | F8: 7001020075 | G8: Deepak Pradhan | H8: deepak.pradhan@meesho.com | I8: 9124377820 | J8: Chandan Kumar Goswami | K8: chandan.goswami@meesho.com | L8: 8700962598 | M8: Jamaluddin Khan | N8: jamaluddin.khan@meesho.com | O8: 9040877464
A9: BBS | B9: East | C9: Active | D9: Banit Roy | E9: banit.roy@meesho.com | F9: 7001020075 | G9: Deepak Pradhan | H9: deepak.pradhan@meesho.com | I9: 9124377820 | J9: Pushpa dhwaja hans | K9: puspadhwaja.hans@meesho.com | L9: 9668843849 | M9: Bibhuti Sethy | N9: bibhuti.sethy@meesho.com | O9: 9439315064
A10: MRS | B10: South | C10: Inactive | D10: Vikrant Pandey | E10: vikrant.pandey@meesho.com | F10: 98030 91594 | G10: Praveen Kumar H | H10: praveenkumar.h@meesho.com | I10: 7358110674 | J10: Bhavani Shankar | K10: bhavani.n@meesho.com | L10: 6385797985 | M10: Sheshathri R | N10: Sheshathri.r@meesho.com | O10: 9360681063 | P10: Prathip Raj | Q10: prathipraj.s@meesho.com | R10: 824 875 4934
A11: DSS | B11: North | C11: Inactive | D11: Prince Shukla | E11: prince.shukla@meesho.com | F11: 8097928258 | G11: Ashish Sharma | H11: ashish.sharma2@meesho.com | I11: 9166587996 | J11: surya pratap | K11: surya.pratap@meesho.com | L11: 9451983805
A12: BMS | B12: North | C12: Active | D12: Dhirender Deswal | E12: dhirender.deswal@meesho.com | F12: 9582713760 | G12: Rahul Kumar Mishra | H12: rahul.mishra3@meesho.com | I12: 9212555696 | J12: Ashish Kumar | K12: ashish.kumar4@meesho.com | L12: 6398993379 | M12: Jasveer Singh | N12: jasveer.singh@meesho.com | O12: 9990061118
A13: LOS | B13: North | C13: Active | D13: Prince Shukla | E13: prince.shukla@meesho.com | F13: 8097928258 | G13: Prince Sharma | H13: prince.sharma@meesho.com | I13: 9257905437 | J13: Kuldeep | K13: Kuldeep.kumar2@meesho.com | L13: 7701835822 | M13: Pinto | N13: pintoo.shah@meesho.com | O13: 8800304177
A14: DHS | B14: South | C14: Inactive | D14: Vikrant Pandey | E14: vikrant.pandey@meesho.com | F14: 98030 91594 | G14: Chamar | H14: chamar.munda1@meesho.com | I14: 6363387963 | J14: Bajendra | K14: bajendra.rauta@meesho.com | L14: 7624961 553 | N14: prashant.pothdar@meesho.com | O14: 9513666556 | P14: Farukh | Q14: faruk.abdullah@meesho.com | R14: 60009 81093
A15: FRS | B15: North | C15: Active | D15: Prince Shukla | E15: prince.shukla@meesho.com | F15: 8097928258 | G15: Keshav Jee | H15: keshav.jee@meesho.com | I15: 7291972416 | J15: Rohit Dubey | K15: rohit.dubey@meesho.com | L15: 8234854147
A16: DLS | B16: North | C16: Active | D16: Dhirender Deswal | E16: dhirender.deswal@meesho.com | F16: 9582713760 | G16: Alan Winsent Martin | H16: alan.martin@meesho.com | I16: 8527384707 | J16: Sombir | K16: sombir@meesho.com | L16: 8278982239 | M16: Arvind Yadav | N16: arvind.yadav@meesho.com | O16: 7056497596
A17: GAS | B17: North | C17: Inactive | D17: Prince Shukla | E17: prince.shukla@meesho.com | F17: 8097928258 | G17: Ashish Sharma | H17: ashish.sharma2@meesho.com | I17: 9166587996
A18: GUS | B18: North | C18: Active | D18: Prince Shukla | E18: prince.shukla@meesho.com | F18: 8097928258 | G18: Vishnu Dutta Mishra | H18: vishnu.mishra1@meesho.com | I18: 6388563799 | J18: surya pratap | K18: surya.pratap@meesho.com | L18: 9451983805 | M18: Akshay Kumar | N18: Akshay.kumar1@meesho.com | O18: 9811699234
A19: DGS1 | B19: North | C19: Active | D19: Prince Shukla | E19: prince.shukla@meesho.com | F19: 8097928258 | G19: Akshit Ahuja | H19: akshit.ahuja@meesho.com | I19: 9266806499 | J19: Rajesh | K19: rajesh.yadav@meesho.com | L19: 9718167299
A20: TVNS | B20: North | C20: Inactive | D20: Prince Shukla | E20: prince.shukla@meesho.com | F20: 8097928258 | G20: Vishnu Dutta Mishra | H20: vishnu.mishra1@meesho.com | I20: 6388563799
A21: GPS | B21: East | C21: Active | D21: Banit Roy | E21: banit.roy@meesho.com | F21: 7001020075 | G21: Suraj kumar | H21: suraj.kumar2@meesho.com | I21: 7979735523 | J21: Satrughan Kumar | K21: satrughan.chourasia@meesho.com | L21: 9570715341 | M21: Alok anupam | N21: alok.anupam@meesho.com | O21: 7903508833
A22: GHS | B22: East | C22: Active | D22: Banit Roy | E22: banit.roy@meesho.com | F22: 7001020075 | G22: Suren Hazarika | H22: suren.hazarika@meesho.com | I22: 6000836880 | J22: Deepjyoti Talukdar | K22: deepjyoti.talukdar@meesho.com | L22: 9387469513 | M22: Brij kishore chauhan | N22: brij.chauhan@meesho.com | O22: 8638190824 | P22: Dipjyoti Dey | Q22: dipjyoti.dey@meesho.com | R22: 9706785585
A23: DBS | B23: East | C23: Active | D23: Banit Roy | E23: banit.roy@meesho.com | F23: 7001020075 | G23: Suren Hazarika | H23: suren.hazarika@meesho.com | I23: 6000836880 | J23: Surya Deep Das | K23: surya.das@meesho.com | L23: 8486874991 | N23: bikash.borah@meesho.com | O23: 8811811385
A24: FKS | B24: North | C24: Active | D24: Dhirender Deswal | E24: dhirender.deswal@meesho.com | F24: 9582713760 | G24: Alan Winsent Martin | H24: alan.martin@meesho.com | I24: 8527384707 | J24: Indu | K24: indu@meesho.com | L24: 7027669312 | M24: Sonu Yadav | N24: sonu.yadav@meesho.com | O24: 8059776160
A25: HGS | B25: East | C25: Inactive | D25: Banit Roy | E25: banit.roy@meesho.com | F25: 7001020075 | G25: Anupam Bal | H25: anupam.bal@meesho.com | I25: 7001483429 | J25: Barun Santra | K25: barun.santra@meesho.com | L25: 6294745548 | M25: Saikat Debnath | N25: saikat.debnath@meesho.com | O25: 70032 86129
A26: HYS | B26: South | C26: Inactive | D26: Vikrant Pandey | E26: vikrant.pandey@meesho.com | F26: 98030 91594 | G26: Pavan Kumar | H26: Pavan.kumar1@meesho.com | I26: 8550010045 | J26: "Pakkula Sathish" | K26: yerrabonia.kumar@meesho.com | L26: 7981426204 | M26: Bommi Nagesh | N26: bommi.nagesh@meesho.com | O26: 9966153878
A27: JBS | B27: West | C27: Active | D27: Ajit Gajana Vedak | E27: ajit.vedak@meesho.com | F27: 9004551388 | G27: Axendra Singh Chouhan | H27: axendra.chouhan@meesho.com | I27: 7024477807 | J27: Gaurav Tayade | K27: gaurav.tayade@meesho.com | L27: 7378792307 | M27: Durgesh kori | N27: durgesh.kori@meesho.com | O27: 7999541157 | P27: Pushpendra kumar patel | Q27: pushpendra.patel@meesho.com | R27: 8319900868
A28: JAS | B28: West | C28: Inactive | D28: Ajit Gajana Vedak | E28: ajit.vedak@meesho.com | F28: 9004551388 | G28: Vikram Singh Rathore | H28: vikram.rathore1@meesho.com | I28: 9413978081 | J28: DUSHYANT KUMAR | K28: dushyant.kumar@meesho.com | L28: 8192051386 | M28: Mantesh Kumar Bairwa | N28: mantesh.bairwa@meesho.com | O28: 9650365405
A29: JPS | B29: West | C29: Active | D29: Ajit Gajana Vedak | E29: ajit.vedak@meesho.com | F29: 9004551388 | G29: Vikram Singh Rathore | H29: vikram.rathore1@meesho.com | I29: 9413978081 | J29: Piyush Singh | K29: piyush.singh@meesho.com | L29: 6352662236 | M29: Abdul Rahuf | N29: abdul.rahuf@meesho.com | O29: 8107269797
A30: JIS | B30: West | C30: Active | D30: Ajit Gajana Vedak | E30: ajit.vedak@meesho.com | F30: 9004551388 | G30: Indu Bala | H30: indu.bala@meesho.com | I30: 8826836418 | J30: Sonu Bairwa | K30: sonu.bairwa@meesho.com | L30: 9358389188 | M30: Rohit Singh Shekhawat | N30: rohit.shekhawat@meesho.com | O30: 9119295841
A31: JUS | B31: West | C31: Inactive | D31: Ajit Gajana Vedak | E31: ajit.vedak@meesho.com | F31: 9004551388 | G31: Vikram Singh Rathore | H31: vikram.rathore1@meesho.com | I31: 9413978081
A32: JJS | B32: West | C32: Active | D32: Ajit Gajana Vedak | E32: ajit.vedak@meesho.com | F32: 9004551388 | G32: Vikram Singh Rathore | H32: vikram.rathore1@meesho.com | I32: 9413978081 | J32: SOURABH SAIN | K32: sourabh.sain@meesho.com | L32: 8952933305 | M32: Gyan Bahadur Jaiswal | N32: gyan.jaiswal@meesho.com | O32: 9318344671
A33: KBS | B33: North | C33: Active | D33: Tushar Sharma | E33: tushar.sharma@meesho.com | F33: 8591391390 | G33: Suraj Chaturvedi | H33: suraj.chaturvedi1@meesho.com | I33: 6393102570 | J33: Amrendra singh | K33: amrendra.singh@meesho.com | L33: 8400863508 | M33: Rituraj gupta | N33: rituraj.gupta@meesho.com | O33: 9696055700
A34: KYS | B34: South | C34: Inactive | D34: Vikrant Pandey | E34: vikrant.pandey@meesho.com | F34: 98030 91594 | G34: Joseph Cherian | H34: joseph.cherian@meesho.com | I34: 8129603774
A35: KOS | B35: East | C35: Active | D35: Banit Roy | E35: banit.roy@meesho.com | F35: 7001020075 | G35: Anupam Bal | H35: anupam.bal@meesho.com | I35: 7001483429 | J35: Pritam Ghosh | K35: pritam.ghosh@meesho.com | L35: 8910122638 | M35: Tapas Bhuinya | N35: tapas.bhuinya@meesho.com | O35: 4ls | P35: Md Sahid Mostafa Tarafdar | Q35: md.tarafdar@meesho.com | R35: 8777826460
A36: LKS | B36: North | C36: Inactive | D36: Tushar Sharma | E36: tushar.sharma@meesho.com | F36: 8591391390 | G36: Suraj Chaturvedi | H36: suraj.chaturvedi1@meesho.com | I36: 6393102570 | J36: Aman Mishra | K36: aman.mishra@meesho.com | L36: 8922876280 | M36: Umakant Maurya | N36: umakant.maurya@meesho.com | O36: 8574176858
A37: VSS | B37: North | C37: Active | D37: Tushar Sharma | E37: tushar.sharma@meesho.com | F37: 8591391390 | G37: Suraj Chaturvedi | H37: suraj.chaturvedi1@meesho.com | I37: 6393102570 | J37: Ramnaresh Dwivedi | K37: ramnaresh.dwivedi@meesho.com | L37: 8090632265 | M37: Ajeet Kumar Singh | N37: ajeet.singh@meesho.com | O37: 7311120913
A38: LUS | B38: North | C38: Inactive | D38: Tushar Sharma | E38: tushar.sharma@meesho.com | F38: 8591391390 | G38: Sourav Nath | H38: sourav.mishra@meesho.com | I38: 9888665095 | J38: Arwinder Singh | K38: arwinder.singh@meesho.com | L38: 8847290992 | M38: Arun Prashar | N38: arun.prasher@meesho.com | O38: 97817 67191
A39: LAS | B39: North | C39: Active | D39: Tushar Sharma | E39: tushar.sharma@meesho.com | F39: 8591391390 | G39: Sourav Nath | H39: sourav.mishra@meesho.com | I39: 9888665095 | J39: Arun Prashar | K39: arun.prasher@meesho.com | L39: 97817 67191 | M39: Gurjit Singh | N39: gurjit.singh@meesho.com | O39: 9872875565
A40: DCS | B40: North | C40: Active | D40: Prince Shukla | E40: prince.shukla@meesho.com | F40: 8097928258 | G40: Mukesh Singh | H40: mukesh.singh@meesho.com | I40: 9999182731 | J40: Bhupender | K40: bhupender@meesho.com | L40: 8708294939 | M40: Sourabh Kumar | N40: sourabh.kumar1@meesho.com | O40: 9888665095
...

Sheet sheet3
A1: Zone | B1: Designation | C1: Name | D1: Mail ID | E1: Mobile Number | F1: Password
A2: =_xlfn.XLOOKUP(D2,sheet2!E:E,sheet2!B:B,1,0) -> West | B2: Regional Head | C2: Tushar Dongare | D2: tushar.dongare@meesho.com | E2: 8007696417 | F2: =E2 -> 8007696417
A3: =_xlfn.XLOOKUP(D3,sheet2!E:E,sheet2!B:B,1,0) -> South | B3: Regional Head | C3: Vikrant Pandey | D3: vikrant.pandey@meesho.com | E3: 98030 91594 | F3: =E3 -> 98030 91594
A4: =_xlfn.XLOOKUP(D4,sheet2!E:E,sheet2!B:B,1,0) -> West | B4: Regional Head | C4: Ajit Gajana Vedak | D4: ajit.vedak@meesho.com | E4: 9004551388 | F4: =E4 -> 9004551388
A5: =_xlfn.XLOOKUP(D5,sheet2!E:E,sheet2!B:B,1,0) -> East | B5: Regional Head | C5: Banit Roy | D5: banit.roy@meesho.com | E5: 7001020075 | F5: =E5 -> 7001020075
A6: =_xlfn.XLOOKUP(D6,sheet2!E:E,sheet2!B:B,1,0) -> North | B6: Regional Head | C6: Prince Shukla | D6: prince.shukla@meesho.com | E6: 8097928258 | F6: =E6 -> 8097928258
A7: =_xlfn.XLOOKUP(D7,sheet2!E:E,sheet2!B:B,1,0) -> North | B7: Regional Head | C7: Dhirender Deswal | D7: dhirender.deswal@meesho.com | E7: 9582713760 | F7: =E7 -> 9582713760
A8: =_xlfn.XLOOKUP(D8,sheet2!E:E,sheet2!B:B,1,0) -> North | B8: Regional Head | C8: Tushar Sharma | D8: tushar.sharma@meesho.com | E8: 8591391390 | F8: =E8 -> 8591391390
A9: =_xlfn.XLOOKUP(D9,sheet2!H:H,sheet2!B:B,1,0) -> West | B9: Cluster Head | C9: Siddharth Chhibber | D9: siddharth.chhibber@meesho.com | E9: 8160593572 | F9: =E9 -> 8160593572
A10: =_xlfn.XLOOKUP(D10,sheet2!H:H,sheet2!B:B,1,0) -> South | B10: Cluster Head | C10: Sujesh S | D10: Sujesh.s@meesho.com | E10: 9497320464 | F10: =E10 -> 9497320464
A11: =_xlfn.XLOOKUP(D11,sheet2!H:H,sheet2!B:B,1,0) -> South | B11: Cluster Head | C11: Chamar | D11: chamar.munda1@meesho.com | E11: 6363387963 | F11: =E11 -> 6363387963
A12: =_xlfn.XLOOKUP(D12,sheet2!H:H,sheet2!B:B,1,0) -> West | B12: Cluster Head | C12: Suresh Behera | D12: Suresh.behera@meesho.com | E12: 8355872770 | F12: =E12 -> 8355872770
A13: =_xlfn.XLOOKUP(D13,sheet2!H:H,sheet2!B:B,1,0) -> West | B13: Cluster Head | C13: Abhishek Mhamunkar | D13: abhishek.mhamunkar@meesho.com | E13: 9969276834 | F13: =E13 -> 9969276834
A14: =_xlfn.XLOOKUP(D14,sheet2!H:H,sheet2!B:B,1,0) -> West | B14: Cluster Head | C14: Axendra Singh Chouhan | D14: axendra.chouhan@meesho.com | E14: 7024477807 | F14: =E14 -> 7024477807
A15: =_xlfn.XLOOKUP(D15,sheet2!H:H,sheet2!B:B,1,0) -> East | B15: Cluster Head | C15: Deepak Pradhan | D15: deepak.pradhan@meesho.com | E15: 9124377820 | F15: =E15 -> 9124377820
A16: =_xlfn.XLOOKUP(D16,sheet2!H:H,sheet2!B:B,1,0) -> South | B16: Cluster Head | C16: Praveen Kumar H | D16: praveenkumar.h@meesho.com | E16: 7358110674 | F16: =E16 -> 7358110674
A17: =_xlfn.XLOOKUP(D17,sheet2!H:H,sheet2!B:B,1,0) -> North | B17: Cluster Head | C17: Ashish Sharma | D17: ashish.sharma2@meesho.com | E17: 9166587996 | F17: =E17 -> 9166587996
A18: =_xlfn.XLOOKUP(D18,sheet2!H:H,sheet2!B:B,1,0) -> North | B18: Cluster Head | C18: Rahul Kumar Mishra | D18: rahul.mishra3@meesho.com | E18: 9212555696 | F18: =E18 -> 9212555696
A19: =_xlfn.XLOOKUP(D19,sheet2!H:H,sheet2!B:B,1,0) -> North | B19: Cluster Head | C19: Prince Sharma | D19: prince.sharma@meesho.com | E19: 9257905437 | F19: =E19 -> 9257905437
A20: =_xlfn.XLOOKUP(D20,sheet2!H:H,sheet2!B:B,1,0) -> North | B20: Cluster Head | C20: Keshav Jee | D20: keshav.jee@meesho.com | E20: 7291972416 | F20: =E20 -> 7291972416
... A33: =_xlfn.XLOOKUP(D33,sheet2!H:H,sheet2!B:B,1,0) -> North | B33: Cluster Head | C33: Mukesh Singh | D33: mukesh.singh@meesho.com | E33: 9999182731 | F33: =E33 -> 9999182731
A34: =_xlfn.XLOOKUP(D34,sheet2!H:H,sheet2!B:B,1,0) -> West | B34: Cluster Head | C34: Vaibhav Bhadake | D34: vaibhav.bhadake1@meesho.com | E34: 97301 82936 | F34: =E34 -> 97301 82936
A35: =_xlfn.XLOOKUP(D35,sheet2!H:H,sheet2!B:B,1,0) -> East | B35: Cluster Head | C35: Himanshu kumar | D35: himanshu.kumar2@meesho.com | E35: 7992351620 | F35: =E35 -> 7992351620
A36: =_xlfn.XLOOKUP(D36,sheet2!H:H,sheet2!B:B,1,0) -> West | B36: Cluster Head | C36: Nilesh Parbhane | D36: nilesh.parbhane@meesho.com | E36: 8806659691 | F36: =E36 -> 8806659691
A37: =_xlfn.XLOOKUP(D37,sheet2!H:H,sheet2!B:B,1,0) -> West | B37: Cluster Head | C37: Rohit Kakade | D37: rohit.kakade@meesho.com | E37: 7028402715 | F37: =E37 -> 7028402715
A38: =_xlfn.XLOOKUP(D38,sheet2!H:H,sheet2!B:B,1,0) -> East | B38: Cluster Head | C38: Pradip Kumar | D38: pradip.kumar@meesho.com | E38: 9303626268 | F38: =E38 -> 9303626268
A39: =_xlfn.XLOOKUP(D39,sheet2!H:H,sheet2!B:B,1,0) -> North | B39: Cluster Head | C39: Navneet Kumar | D39: navneet.kumar1@meesho.com | E39: 9027246940 | F39: =E39 -> 9027246940
A40: =_xlfn.XLOOKUP(D40,sheet2!H:H,sheet2!B:B,1,0) -> West | B40: Cluster Head | C40: Mukesh Patil | D40: mukesh.patil@meesho.com | E40: 7698837388 | F40: =E40 -> 7698837388
A41: =_xlfn.XLOOKUP(D41,sheet2!H:H,sheet2!B:B,1,0) -> West | B41: Cluster Head | C41: Pankaj Tripathi | D41: pankaj.tripathi@meesho.com | E41: 8930909315 | F41: =E41 -> 8930909315
A42: =_xlfn.XLOOKUP(D42,sheet2!H:H,sheet2!B:B,1,0) -> West | B42: Cluster Head | C42: Sudhir Pratap Singh | D42: Sudhir.singh@meesho.com | E42: 7016450894 | F42: =E42 -> 7016450894
A43: =_xlfn.XLOOKUP(D43,sheet2!H:H,sheet2!B:B,1,0) -> West | B43: Cluster Head | C43: Santosh Kumar Soni | D43: santosh.soni@meesho.com | E43: 9099201055 | F43: =E43 -> 9099201055
A44: =_xlfn.XLOOKUP(D44,sheet2!H:H,sheet2!B:B,1,0) -> South | B44: Cluster Head | C44: Kuruba Ravi | D44: Kuruba.ravi@meesho.com | E44: 9133001077 | F44: =E44 -> 9133001077
A45: =_xlfn.XLOOKUP(D45,sheet2!H:H,sheet2!B:B,1,0) -> South | B45: Cluster Head | C45: Karthik | D45: karthik.gunasekaran@meesho.com | E45: 9994448658 | F45: =E45 -> 9994448658
A46: =_xlfn.XLOOKUP(D46,sheet2!H:H,sheet2!B:B,1,0) -> North | B46: Cluster Head | C46: Sandeep Kushwaha | D46: sandeep.kushwaha@meesho.com | E46: 8010417770 | F46: =E46 -> 8010417770
... A55: =_xlfn.XLOOKUP(D55,sheet2!H:H,sheet2!B:B,1,0) -> West | B55: Cluster Head | C55: Vijay Kumar Sharma | D55: vijay.sharma1@meesho.com | E55: 9712948673 | F55: =E55 -> 9712948673
A56: =_xlfn.XLOOKUP(D56,sheet2!K:K,sheet2!B:B,1,0) -> West | B56: Area Manager | C56: Prakash Lokhande | D56: lokhnade.prakash@meesho.com | E56: 9173700204 | F56: =E56 -> 9173700204
A57: =_xlfn.XLOOKUP(D57,sheet2!K:K,sheet2!B:B,1,0) -> South | B57: Area Manager | C57: Shivaraj | D57: shivraj.a@meesho.com | E57: 90366 61602 | F57: =E57 -> 90366 61602
A58: =_xlfn.XLOOKUP(D58,sheet2!K:K,sheet2!B:B,1,0) -> South | B58: Area Manager | C58: Kishore K L | D58: kishor.kl@meesho.com | E58: 7090078440 | F58: =E58 -> 7090078440
A59: =_xlfn.XLOOKUP(D59,sheet2!K:K,sheet2!B:B,1,0) -> West | B59: Area Manager | C59: Awwab Kirme | D59: awwab.kirme@meesho.com | E59: 8888726472 | F59: =E59 -> 8888726472
A60: =_xlfn.XLOOKUP(D60,sheet2!K:K,sheet2!B:B,1,0) -> West | B60: Area Manager | C60: Amar Pansare | D60: amar.pansare@meesho.com | E60: 7767908097 | F60: =E60 -> 7767908097
...
